<?xml version="1.0"?>

<robot name="smartcar" >

    <link name="base_footprint">
        <visual>
            <origin xyz="0 0 0" rpy="0 0 0" />
            <geometry>
                <box size="0.001 0.001 0.001" />
            </geometry>
        </visual>
    </link>
    <joint name="base_footprint_joint" type="fixed">
        <origin rpy="0 0 0" xyz="0 0 0.05" />
        <parent link="base_footprint" />
        <child link="base_link" />
    </joint>

    <link name="base_link">
        <visual>
            <geometry>
                <box size="0.25 .16 .05"/>
            </geometry>
            <origin rpy="0 0 0" xyz="0 0 0"/>
            <material name="blue">
                <color rgba="0 0 .8 1"/>
            </material>
        </visual>

        <collision>
            <geometry>
                <box size="0.25 .16 .05"/>
            </geometry>
        </collision>
        <inertial>
            <mass value="10"/>
            <inertia ixx="1.0" ixy="0.0" ixz="0.0"
                     iyy="1.0" iyz="0.0" izz="1.0"/>
        </inertial>

    </link>

    <link name="right_front_wheel">
        <visual>
            <geometry>
                <cylinder length=".02" radius="0.025"/>
            </geometry>
            <material name="red">
                <color rgba="1 0 0 1"/>
            </material>
        </visual>

        <collision>
            <geometry>
                <cylinder length=".02" radius="0.025"/>
            </geometry>
        </collision>
        <inertial>
            <mass value="1"/>
            <inertia ixx="1.0" ixy="0.0" ixz="0.0"
                     iyy="1.0" iyz="0.0" izz="1.0"/>
        </inertial>
    </link>

    <joint name="right_front_wheel_joint" type="continuous">
        <axis xyz="0 0 1"/>
        <parent link="base_link"/>
        <child link="right_front_wheel"/>
        <origin rpy="1.57 0 0" xyz="0.08 -0.085 -0.025"/>
        <limit effort="100" velocity="100"/>
        <joint_properties damping="0.0" friction="0.0"/>

    </joint>

    <link name="right_back_wheel">
        <visual>
            <geometry>
                <cylinder length=".02" radius="0.025"/>
            </geometry>
            <material name="black">
                <color rgba="0 0 0 1"/>
            </material>
        </visual>

        <collision>
            <geometry>
                <cylinder length=".02" radius="0.025"/>
            </geometry>
        </collision>
        <inertial>
            <mass value="1"/>
            <inertia ixx="1.0" ixy="0.0" ixz="0.0"
                     iyy="1.0" iyz="0.0" izz="1.0"/>
        </inertial>
    </link>

    <joint name="right_back_wheel_joint" type="continuous">
        <axis xyz="0 0 1"/>
        <parent link="base_link"/>
        <child link="right_back_wheel"/>
        <origin rpy="1.57 0 0" xyz="-0.08 -0.085 -0.025"/>
        <limit effort="100" velocity="100"/>
        <joint_properties damping="0.0" friction="0.0"/>
    </joint>

    <link name="left_front_wheel">
        <visual>
            <geometry>
                <cylinder length=".02" radius="0.025"/>
            </geometry>
            <material name="black">
                <color rgba="0 0 0 1"/>
            </material>
        </visual>

        <collision>
            <geometry>
                <cylinder length=".02" radius="0.025"/>
            </geometry>
        </collision>
        <inertial>
            <mass value="1"/>
            <inertia ixx="1.0" ixy="0.0" ixz="0.0"
                     iyy="1.0" iyz="0.0" izz="1.0"/>
        </inertial>
    </link>

    <joint name="left_front_wheel_joint" type="continuous">
        <axis xyz="0 0 1"/>
        <parent link="base_link"/>
        <child link="left_front_wheel"/>
        <origin rpy="1.57 0 0" xyz="0.08 0.085 -0.025"/>
        <limit effort="100" velocity="100"/>
        <joint_properties damping="0.0" friction="0.0"/>
    </joint>

    <link name="left_back_wheel">
        <visual>
            <geometry>
                <cylinder length=".02" radius="0.025"/>
            </geometry>
            <material name="black">
                <color rgba="0 0 0 1"/>
            </material>
        </visual>

        <collision>
            <geometry>
                <cylinder length=".02" radius="0.025"/>
            </geometry>
        </collision>
        <inertial>
            <mass value="1"/>
            <inertia ixx="1.0" ixy="0.0" ixz="0.0"
                     iyy="1.0" iyz="0.0" izz="1.0"/>
        </inertial>
    </link>

    <joint name="left_back_wheel_joint" type="continuous">
        <axis xyz="0 0 1"/>
        <parent link="base_link"/>
        <child link="left_back_wheel"/>
        <origin rpy="1.57 0 0" xyz="-0.08 0.085 -0.025"/>
        <limit effort="100" velocity="100"/>
        <joint_properties damping="0.0" friction="0.0"/>
    </joint>

    <link name="head">
        <visual>
            <geometry>
                <box size=".02 .03 .03"/>
            </geometry>
            <material name="white">
                <color rgba="1 1 1 1"/>
            </material>
        </visual>

        <collision>
            <geometry>
                <box size=".02 .03 .03"/>
            </geometry>
        </collision>
        <inertial>
            <mass value="1"/>
            <inertia ixx="1.0" ixy="0.0" ixz="0.0"
                     iyy="1.0" iyz="0.0" izz="1.0"/>
        </inertial>
    </link>

    <joint name="tobox" type="fixed">
        <parent link="base_link"/>
        <child link="head"/>
        <origin xyz="0.1 0 0.04"/>
    </joint>


    <!-- Drive controller -->
    <gazebo>
        <plugin name="skid_steer_drive_controller" filename="libgazebo_ros_skid_steer_drive.so">
            <updateRate>100.0</updateRate>
            <robotNamespace>/</robotNamespace>
            <leftFrontJoint>left_front_wheel_joint</leftFrontJoint>
            <rightFrontJoint>right_front_wheel_joint</rightFrontJoint>
            <leftRearJoint>left_back_wheel_joint</leftRearJoint>
            <rightRearJoint>right_back_wheel_joint</rightRearJoint>
            <wheelSeparation>0.17</wheelSeparation>
            <wheelDiameter>0.05</wheelDiameter>
            <commandTopic>cmd_vel</commandTopic>
            <odometryTopic>odom</odometryTopic>
            <robotBaseFrame>base_footprint</robotBaseFrame>
            <odometryFrame>odom</odometryFrame>
            <torque>1</torque>
            <topicName>cmd_vel</topicName>
            <broadcastTF>1</broadcastTF>
        </plugin>
    </gazebo>

    <!-- ros_control plugin -->
    <gazebo>
        <plugin name="gazebo_ros_control" filename="libgazebo_ros_control.so">
            <robotNamespace>/robot1</robotNamespace>
            <legacyModeNS>true</legacyModeNS>
        </plugin>
    </gazebo>
</robot>